2020-12-10 15:43:22,962 ERROR: Exception on /add_hkpost [POST] [in C:\Users\fungz\AppData\Local\Programs\Python\Python37-32\lib\site-packages\flask\app.py:1891]
Traceback (most recent call last):
  File "C:\Users\fungz\AppData\Local\Programs\Python\Python37-32\lib\site-packages\sqlalchemy\engine\base.py", line 1248, in _execute_context
    cursor, statement, parameters, context
  File "C:\Users\fungz\AppData\Local\Programs\Python\Python37-32\lib\site-packages\sqlalchemy\engine\default.py", line 588, in do_execute
    cursor.execute(statement, parameters)
sqlite3.OperationalError: table hkpost has no column named site

The above exception was the direct cause of the following exception:

Traceback (most recent call last):
  File "C:\Users\fungz\AppData\Local\Programs\Python\Python37-32\lib\site-packages\flask\app.py", line 2446, in wsgi_app
    response = self.full_dispatch_request()
  File "C:\Users\fungz\AppData\Local\Programs\Python\Python37-32\lib\site-packages\flask\app.py", line 1951, in full_dispatch_request
    rv = self.handle_user_exception(e)
  File "C:\Users\fungz\AppData\Local\Programs\Python\Python37-32\lib\site-packages\flask\app.py", line 1820, in handle_user_exception
    reraise(exc_type, exc_value, tb)
  File "C:\Users\fungz\AppData\Local\Programs\Python\Python37-32\lib\site-packages\flask\_compat.py", line 39, in reraise
    raise value
  File "C:\Users\fungz\AppData\Local\Programs\Python\Python37-32\lib\site-packages\flask\app.py", line 1949, in full_dispatch_request
    rv = self.dispatch_request()
  File "C:\Users\fungz\AppData\Local\Programs\Python\Python37-32\lib\site-packages\flask\app.py", line 1935, in dispatch_request
    return self.view_functions[rule.endpoint](**req.view_args)
  File "C:\Users\fungz\PycharmProjects\Ulifestyle\ulifestyle_folder\app\routes.py", line 374, in add_hkpost
    db.session.commit()
  File "C:\Users\fungz\AppData\Local\Programs\Python\Python37-32\lib\site-packages\sqlalchemy\orm\scoping.py", line 162, in do
    return getattr(self.registry(), name)(*args, **kwargs)
  File "C:\Users\fungz\AppData\Local\Programs\Python\Python37-32\lib\site-packages\sqlalchemy\orm\session.py", line 1036, in commit
    self.transaction.commit()
  File "C:\Users\fungz\AppData\Local\Programs\Python\Python37-32\lib\site-packages\sqlalchemy\orm\session.py", line 503, in commit
    self._prepare_impl()
  File "C:\Users\fungz\AppData\Local\Programs\Python\Python37-32\lib\site-packages\sqlalchemy\orm\session.py", line 482, in _prepare_impl
    self.session.flush()
  File "C:\Users\fungz\AppData\Local\Programs\Python\Python37-32\lib\site-packages\sqlalchemy\orm\session.py", line 2496, in flush
    self._flush(objects)
  File "C:\Users\fungz\AppData\Local\Programs\Python\Python37-32\lib\site-packages\sqlalchemy\orm\session.py", line 2637, in _flush
    transaction.rollback(_capture_exception=True)
  File "C:\Users\fungz\AppData\Local\Programs\Python\Python37-32\lib\site-packages\sqlalchemy\util\langhelpers.py", line 69, in __exit__
    exc_value, with_traceback=exc_tb,
  File "C:\Users\fungz\AppData\Local\Programs\Python\Python37-32\lib\site-packages\sqlalchemy\util\compat.py", line 178, in raise_
    raise exception
  File "C:\Users\fungz\AppData\Local\Programs\Python\Python37-32\lib\site-packages\sqlalchemy\orm\session.py", line 2597, in _flush
    flush_context.execute()
  File "C:\Users\fungz\AppData\Local\Programs\Python\Python37-32\lib\site-packages\sqlalchemy\orm\unitofwork.py", line 422, in execute
    rec.execute(self)
  File "C:\Users\fungz\AppData\Local\Programs\Python\Python37-32\lib\site-packages\sqlalchemy\orm\unitofwork.py", line 589, in execute
    uow,
  File "C:\Users\fungz\AppData\Local\Programs\Python\Python37-32\lib\site-packages\sqlalchemy\orm\persistence.py", line 245, in save_obj
    insert,
  File "C:\Users\fungz\AppData\Local\Programs\Python\Python37-32\lib\site-packages\sqlalchemy\orm\persistence.py", line 1136, in _emit_insert_statements
    statement, params
  File "C:\Users\fungz\AppData\Local\Programs\Python\Python37-32\lib\site-packages\sqlalchemy\engine\base.py", line 984, in execute
    return meth(self, multiparams, params)
  File "C:\Users\fungz\AppData\Local\Programs\Python\Python37-32\lib\site-packages\sqlalchemy\sql\elements.py", line 293, in _execute_on_connection
    return connection._execute_clauseelement(self, multiparams, params)
  File "C:\Users\fungz\AppData\Local\Programs\Python\Python37-32\lib\site-packages\sqlalchemy\engine\base.py", line 1103, in _execute_clauseelement
    distilled_params,
  File "C:\Users\fungz\AppData\Local\Programs\Python\Python37-32\lib\site-packages\sqlalchemy\engine\base.py", line 1288, in _execute_context
    e, statement, parameters, cursor, context
  File "C:\Users\fungz\AppData\Local\Programs\Python\Python37-32\lib\site-packages\sqlalchemy\engine\base.py", line 1482, in _handle_dbapi_exception
    sqlalchemy_exception, with_traceback=exc_info[2], from_=e
  File "C:\Users\fungz\AppData\Local\Programs\Python\Python37-32\lib\site-packages\sqlalchemy\util\compat.py", line 178, in raise_
    raise exception
  File "C:\Users\fungz\AppData\Local\Programs\Python\Python37-32\lib\site-packages\sqlalchemy\engine\base.py", line 1248, in _execute_context
    cursor, statement, parameters, context
  File "C:\Users\fungz\AppData\Local\Programs\Python\Python37-32\lib\site-packages\sqlalchemy\engine\default.py", line 588, in do_execute
    cursor.execute(statement, parameters)
sqlalchemy.exc.OperationalError: (sqlite3.OperationalError) table hkpost has no column named site
[SQL: INSERT INTO hkpost (title, author, body1, body2, timestamp, theme, tag, type, site) VALUES (?, ?, ?, ?, ?, ?, ?, ?, ?)]
[parameters: ('bhj', None, 'vh', 'gjh', '2020-12-10 07:43:22.958719', 'v', 'j', 'article', 'HK')]
(Background on this error at: http://sqlalche.me/e/e3q8)
2020-12-10 15:45:18,469 INFO: Microblog startup [in C:\Users\fungz\PycharmProjects\Ulifestyle\ulifestyle_folder\app\__init__.py:46]
2020-12-10 15:45:49,912 INFO: Microblog startup [in C:\Users\fungz\PycharmProjects\Ulifestyle\ulifestyle_folder\app\__init__.py:46]
2020-12-10 15:46:44,795 INFO: Microblog startup [in C:\Users\fungz\PycharmProjects\Ulifestyle\ulifestyle_folder\app\__init__.py:46]
2020-12-10 15:47:31,202 INFO: Microblog startup [in C:\Users\fungz\PycharmProjects\Ulifestyle\ulifestyle_folder\app\__init__.py:46]
2020-12-10 15:54:48,283 INFO: Microblog startup [in C:\Users\fungz\PycharmProjects\Ulifestyle\ulifestyle_folder\app\__init__.py:46]
2020-12-10 15:54:59,003 ERROR: Exception on /add_hkpost [POST] [in C:\Users\fungz\AppData\Local\Programs\Python\Python37-32\lib\site-packages\flask\app.py:1891]
Traceback (most recent call last):
  File "C:\Users\fungz\AppData\Local\Programs\Python\Python37-32\lib\site-packages\flask\app.py", line 2446, in wsgi_app
    response = self.full_dispatch_request()
  File "C:\Users\fungz\AppData\Local\Programs\Python\Python37-32\lib\site-packages\flask\app.py", line 1951, in full_dispatch_request
    rv = self.handle_user_exception(e)
  File "C:\Users\fungz\AppData\Local\Programs\Python\Python37-32\lib\site-packages\flask\app.py", line 1820, in handle_user_exception
    reraise(exc_type, exc_value, tb)
  File "C:\Users\fungz\AppData\Local\Programs\Python\Python37-32\lib\site-packages\flask\_compat.py", line 39, in reraise
    raise value
  File "C:\Users\fungz\AppData\Local\Programs\Python\Python37-32\lib\site-packages\flask\app.py", line 1949, in full_dispatch_request
    rv = self.dispatch_request()
  File "C:\Users\fungz\AppData\Local\Programs\Python\Python37-32\lib\site-packages\flask\app.py", line 1935, in dispatch_request
    return self.view_functions[rule.endpoint](**req.view_args)
  File "C:\Users\fungz\PycharmProjects\Ulifestyle\ulifestyle_folder\app\routes.py", line 361, in add_hkpost
    site=form.site.data,
AttributeError: 'PostForm' object has no attribute 'site'
2020-12-10 15:55:18,887 INFO: Microblog startup [in C:\Users\fungz\PycharmProjects\Ulifestyle\ulifestyle_folder\app\__init__.py:46]
2020-12-10 16:25:25,341 INFO: Microblog startup [in C:\Users\fungz\PycharmProjects\Ulifestyle\ulifestyle_folder\app\__init__.py:46]
